2019-04-04 16:29:50,045-ERROR-Internal Server Error: /api/v1/apiTypeTest/
Traceback (most recent call last):
  File "d:\Anaconda3\lib\site-packages\django\core\handlers\exception.py", line 34, in inner
    response = get_response(request)
  File "d:\Anaconda3\lib\site-packages\django\core\handlers\base.py", line 126, in _get_response
    response = self.process_exception_by_middleware(e, request)
  File "d:\Anaconda3\lib\site-packages\django\core\handlers\base.py", line 124, in _get_response
    response = wrapped_callback(request, *callback_args, **callback_kwargs)
  File "d:\Anaconda3\lib\site-packages\django\views\decorators\csrf.py", line 54, in wrapped_view
    return view_func(*args, **kwargs)
  File "d:\Anaconda3\lib\site-packages\django\views\generic\base.py", line 68, in view
    return self.dispatch(request, *args, **kwargs)
  File "d:\Anaconda3\lib\site-packages\rest_framework\views.py", line 495, in dispatch
    response = self.handle_exception(exc)
  File "d:\Anaconda3\lib\site-packages\rest_framework\views.py", line 455, in handle_exception
    self.raise_uncaught_exception(exc)
  File "d:\Anaconda3\lib\site-packages\rest_framework\views.py", line 492, in dispatch
    response = handler(request, *args, **kwargs)
  File "E:\MyWorkSpace\Autotestplat\autotest_drf\user\views.py", line 263, in get
    data = apiTest(url, apiTypes, apiManager, testName=apiManager.apiname, type='∫Û∂À≤‚ ‘')
  File "E:\MyWorkSpace\Autotestplat\autotest_drf\user\tests.py", line 90, in wrapper
    resu = fuc(*args, **kwargs)
TypeError: apiTest() got an unexpected keyword argument 'type'
